[2025-10-20T05:55:17.984+0000] {local_task_job_runner.py:120} INFO - ::group::Pre task execution logs
[2025-10-20T05:55:17.995+0000] {taskinstance.py:2076} INFO - Dependencies all met for dep_context=non-requeueable deps ti=<TaskInstance: events_analytics_pipeline.dbt_docs_generate scheduled__2025-10-20T04:00:00+00:00 [queued]>
[2025-10-20T05:55:17.998+0000] {taskinstance.py:2076} INFO - Dependencies all met for dep_context=requeueable deps ti=<TaskInstance: events_analytics_pipeline.dbt_docs_generate scheduled__2025-10-20T04:00:00+00:00 [queued]>
[2025-10-20T05:55:17.998+0000] {taskinstance.py:2306} INFO - Starting attempt 1 of 3
[2025-10-20T05:55:18.003+0000] {taskinstance.py:2330} INFO - Executing <Task(PythonOperator): dbt_docs_generate> on 2025-10-20 04:00:00+00:00
[2025-10-20T05:55:18.006+0000] {standard_task_runner.py:63} INFO - Started process 958 to run task
[2025-10-20T05:55:18.008+0000] {standard_task_runner.py:90} INFO - Running: ['***', 'tasks', 'run', 'events_analytics_pipeline', 'dbt_docs_generate', 'scheduled__2025-10-20T04:00:00+00:00', '--job-id', '45', '--raw', '--subdir', 'DAGS_FOLDER/events_pipeline_dag.py', '--cfg-path', '/tmp/tmpvwvigxwm']
[2025-10-20T05:55:18.009+0000] {standard_task_runner.py:91} INFO - Job 45: Subtask dbt_docs_generate
[2025-10-20T05:55:18.028+0000] {task_command.py:426} INFO - Running <TaskInstance: events_analytics_pipeline.dbt_docs_generate scheduled__2025-10-20T04:00:00+00:00 [running]> on host 0d320e139cdc
[2025-10-20T05:55:18.058+0000] {taskinstance.py:2648} INFO - Exporting env vars: AIRFLOW_CTX_DAG_OWNER='data-team' AIRFLOW_CTX_DAG_ID='events_analytics_pipeline' AIRFLOW_CTX_TASK_ID='dbt_docs_generate' AIRFLOW_CTX_EXECUTION_DATE='2025-10-20T04:00:00+00:00' AIRFLOW_CTX_TRY_NUMBER='1' AIRFLOW_CTX_DAG_RUN_ID='scheduled__2025-10-20T04:00:00+00:00'
[2025-10-20T05:55:18.058+0000] {taskinstance.py:430} INFO - ::endgroup::
[2025-10-20T05:55:18.064+0000] {events_pipeline_dag.py:148} INFO - Running command: dbt docs generate --profiles-dir /opt/***/.dbt --project-dir /opt/***/event_gen
[2025-10-20T05:55:19.092+0000] {events_pipeline_dag.py:167} ERROR - dbt docs generate failed with error:
Usage: dbt [OPTIONS] COMMAND [ARGS]...
Try 'dbt -h' for help.

Error: No such command 'docs generate'.

[2025-10-20T05:55:19.095+0000] {taskinstance.py:441} INFO - ::group::Post task execution logs
[2025-10-20T05:55:19.095+0000] {taskinstance.py:2905} ERROR - Task failed with exception
Traceback (most recent call last):
  File "/home/airflow/.local/lib/python3.11/site-packages/airflow/models/taskinstance.py", line 465, in _execute_task
    result = _execute_callable(context=context, **execute_callable_kwargs)
             ^^^^^^^^^^^^^^^^^^^^^^^^^^^^^^^^^^^^^^^^^^^^^^^^^^^^^^^^^^^^^
  File "/home/airflow/.local/lib/python3.11/site-packages/airflow/models/taskinstance.py", line 432, in _execute_callable
    return execute_callable(context=context, **execute_callable_kwargs)
           ^^^^^^^^^^^^^^^^^^^^^^^^^^^^^^^^^^^^^^^^^^^^^^^^^^^^^^^^^^^^
  File "/home/airflow/.local/lib/python3.11/site-packages/airflow/models/baseoperator.py", line 401, in wrapper
    return func(self, *args, **kwargs)
           ^^^^^^^^^^^^^^^^^^^^^^^^^^^
  File "/home/airflow/.local/lib/python3.11/site-packages/airflow/operators/python.py", line 235, in execute
    return_value = self.execute_callable()
                   ^^^^^^^^^^^^^^^^^^^^^^^
  File "/home/airflow/.local/lib/python3.11/site-packages/airflow/operators/python.py", line 252, in execute_callable
    return self.python_callable(*self.op_args, **self.op_kwargs)
           ^^^^^^^^^^^^^^^^^^^^^^^^^^^^^^^^^^^^^^^^^^^^^^^^^^^^^
  File "/opt/airflow/dags/events_pipeline_dag.py", line 183, in dbt_docs
    return run_dbt_command("docs generate", **context)
           ^^^^^^^^^^^^^^^^^^^^^^^^^^^^^^^^^^^^^^^^^^^
  File "/opt/airflow/dags/events_pipeline_dag.py", line 151, in run_dbt_command
    result = subprocess.run(
             ^^^^^^^^^^^^^^^
  File "/usr/local/lib/python3.11/subprocess.py", line 571, in run
    raise CalledProcessError(retcode, process.args,
subprocess.CalledProcessError: Command '['dbt', 'docs generate', '--profiles-dir', '/opt/airflow/.dbt', '--project-dir', '/opt/airflow/event_gen']' returned non-zero exit status 2.
[2025-10-20T05:55:19.100+0000] {taskinstance.py:1206} INFO - Marking task as UP_FOR_RETRY. dag_id=events_analytics_pipeline, task_id=dbt_docs_generate, run_id=scheduled__2025-10-20T04:00:00+00:00, execution_date=20251020T040000, start_date=20251020T055517, end_date=20251020T055519
[2025-10-20T05:55:19.105+0000] {standard_task_runner.py:110} ERROR - Failed to execute job 45 for task dbt_docs_generate (Command '['dbt', 'docs generate', '--profiles-dir', '/opt/airflow/.dbt', '--project-dir', '/opt/airflow/event_gen']' returned non-zero exit status 2.; 958)
[2025-10-20T05:55:19.135+0000] {local_task_job_runner.py:240} INFO - Task exited with return code 1
[2025-10-20T05:55:19.142+0000] {taskinstance.py:3503} INFO - 0 downstream tasks scheduled from follow-on schedule check
[2025-10-20T05:55:19.143+0000] {local_task_job_runner.py:222} INFO - ::endgroup::
