[2025-10-17T01:40:40.422+0000] {taskinstance.py:1956} INFO - Dependencies all met for dep_context=non-requeueable deps ti=<TaskInstance: events_analytics_pipeline.dbt_run manual__2025-10-17T01:26:09.897619+00:00 [queued]>
[2025-10-17T01:40:40.425+0000] {taskinstance.py:1956} INFO - Dependencies all met for dep_context=requeueable deps ti=<TaskInstance: events_analytics_pipeline.dbt_run manual__2025-10-17T01:26:09.897619+00:00 [queued]>
[2025-10-17T01:40:40.429+0000] {taskinstance.py:2170} INFO - Starting attempt 3 of 3
[2025-10-17T01:40:40.434+0000] {taskinstance.py:2191} INFO - Executing <Task(BashOperator): dbt_run> on 2025-10-17 01:26:09.897619+00:00
[2025-10-17T01:40:40.437+0000] {standard_task_runner.py:60} INFO - Started process 191 to run task
[2025-10-17T01:40:40.440+0000] {standard_task_runner.py:87} INFO - Running: ['airflow', 'tasks', 'run', 'events_analytics_pipeline', 'dbt_run', 'manual__2025-10-17T01:26:09.897619+00:00', '--job-id', '26', '--raw', '--subdir', 'DAGS_FOLDER/events_pipeline_dag.py', '--cfg-path', '/tmp/tmp1zjabik_']
[2025-10-17T01:40:40.445+0000] {standard_task_runner.py:88} INFO - Job 26: Subtask dbt_run
[2025-10-17T01:40:40.479+0000] {task_command.py:423} INFO - Running <TaskInstance: events_analytics_pipeline.dbt_run manual__2025-10-17T01:26:09.897619+00:00 [running]> on host d7067dead38a
[2025-10-17T01:40:40.518+0000] {taskinstance.py:2480} INFO - Exporting env vars: AIRFLOW_CTX_DAG_OWNER='data-team' AIRFLOW_CTX_DAG_ID='events_analytics_pipeline' AIRFLOW_CTX_TASK_ID='dbt_run' AIRFLOW_CTX_EXECUTION_DATE='2025-10-17T01:26:09.897619+00:00' AIRFLOW_CTX_TRY_NUMBER='3' AIRFLOW_CTX_DAG_RUN_ID='manual__2025-10-17T01:26:09.897619+00:00'
[2025-10-17T01:40:40.519+0000] {subprocess.py:63} INFO - Tmp dir root location: /tmp
[2025-10-17T01:40:40.520+0000] {subprocess.py:75} INFO - Running command: ['/usr/bin/bash', '-c', 'dbt run --profiles-dir /opt/airflow/.dbt --project-dir /opt/airflow/event_gen']
[2025-10-17T01:40:40.526+0000] {subprocess.py:86} INFO - Output:
[2025-10-17T01:40:40.527+0000] {subprocess.py:93} INFO - /usr/bin/bash: line 1: dbt: command not found
[2025-10-17T01:40:40.528+0000] {subprocess.py:97} INFO - Command exited with return code 127
[2025-10-17T01:40:40.533+0000] {taskinstance.py:2698} ERROR - Task failed with exception
Traceback (most recent call last):
  File "/home/airflow/.local/lib/python3.11/site-packages/airflow/models/taskinstance.py", line 433, in _execute_task
    result = execute_callable(context=context, **execute_callable_kwargs)
             ^^^^^^^^^^^^^^^^^^^^^^^^^^^^^^^^^^^^^^^^^^^^^^^^^^^^^^^^^^^^
  File "/home/airflow/.local/lib/python3.11/site-packages/airflow/operators/bash.py", line 212, in execute
    raise AirflowException(
airflow.exceptions.AirflowException: Bash command failed. The command returned a non-zero exit code 127.
[2025-10-17T01:40:40.534+0000] {taskinstance.py:1138} INFO - Marking task as FAILED. dag_id=events_analytics_pipeline, task_id=dbt_run, execution_date=20251017T012609, start_date=20251017T014040, end_date=20251017T014040
[2025-10-17T01:40:40.539+0000] {standard_task_runner.py:107} ERROR - Failed to execute job 26 for task dbt_run (Bash command failed. The command returned a non-zero exit code 127.; 191)
[2025-10-17T01:40:40.581+0000] {local_task_job_runner.py:234} INFO - Task exited with return code 1
[2025-10-17T01:40:40.591+0000] {taskinstance.py:3280} INFO - 0 downstream tasks scheduled from follow-on schedule check
