[2025-10-17T02:33:34.232+0000] {taskinstance.py:1956} INFO - Dependencies all met for dep_context=non-requeueable deps ti=<TaskInstance: events_analytics_pipeline.dbt_run scheduled__2025-10-17T01:00:00+00:00 [queued]>
[2025-10-17T02:33:34.237+0000] {taskinstance.py:1956} INFO - Dependencies all met for dep_context=requeueable deps ti=<TaskInstance: events_analytics_pipeline.dbt_run scheduled__2025-10-17T01:00:00+00:00 [queued]>
[2025-10-17T02:33:34.241+0000] {taskinstance.py:2170} INFO - Starting attempt 3 of 3
[2025-10-17T02:33:34.249+0000] {taskinstance.py:2191} INFO - Executing <Task(BashOperator): dbt_run> on 2025-10-17 01:00:00+00:00
[2025-10-17T02:33:34.254+0000] {standard_task_runner.py:60} INFO - Started process 436 to run task
[2025-10-17T02:33:34.259+0000] {standard_task_runner.py:87} INFO - Running: ['airflow', 'tasks', 'run', 'events_analytics_pipeline', 'dbt_run', 'scheduled__2025-10-17T01:00:00+00:00', '--job-id', '39', '--raw', '--subdir', 'DAGS_FOLDER/events_pipeline_dag.py', '--cfg-path', '/tmp/tmpp3gaviax']
[2025-10-17T02:33:34.261+0000] {standard_task_runner.py:88} INFO - Job 39: Subtask dbt_run
[2025-10-17T02:33:34.298+0000] {task_command.py:423} INFO - Running <TaskInstance: events_analytics_pipeline.dbt_run scheduled__2025-10-17T01:00:00+00:00 [running]> on host d7067dead38a
[2025-10-17T02:33:34.336+0000] {taskinstance.py:2480} INFO - Exporting env vars: AIRFLOW_CTX_DAG_OWNER='data-team' AIRFLOW_CTX_DAG_ID='events_analytics_pipeline' AIRFLOW_CTX_TASK_ID='dbt_run' AIRFLOW_CTX_EXECUTION_DATE='2025-10-17T01:00:00+00:00' AIRFLOW_CTX_TRY_NUMBER='3' AIRFLOW_CTX_DAG_RUN_ID='scheduled__2025-10-17T01:00:00+00:00'
[2025-10-17T02:33:34.337+0000] {subprocess.py:63} INFO - Tmp dir root location: /tmp
[2025-10-17T02:33:34.338+0000] {subprocess.py:75} INFO - Running command: ['/usr/bin/bash', '-c', 'dbt run --profiles-dir /opt/airflow/.dbt --project-dir /opt/airflow/event_gen']
[2025-10-17T02:33:34.343+0000] {subprocess.py:86} INFO - Output:
[2025-10-17T02:33:34.344+0000] {subprocess.py:93} INFO - /usr/bin/bash: line 1: dbt: command not found
[2025-10-17T02:33:34.344+0000] {subprocess.py:97} INFO - Command exited with return code 127
[2025-10-17T02:33:34.351+0000] {taskinstance.py:2698} ERROR - Task failed with exception
Traceback (most recent call last):
  File "/home/airflow/.local/lib/python3.11/site-packages/airflow/models/taskinstance.py", line 433, in _execute_task
    result = execute_callable(context=context, **execute_callable_kwargs)
             ^^^^^^^^^^^^^^^^^^^^^^^^^^^^^^^^^^^^^^^^^^^^^^^^^^^^^^^^^^^^
  File "/home/airflow/.local/lib/python3.11/site-packages/airflow/operators/bash.py", line 212, in execute
    raise AirflowException(
airflow.exceptions.AirflowException: Bash command failed. The command returned a non-zero exit code 127.
[2025-10-17T02:33:34.353+0000] {taskinstance.py:1138} INFO - Marking task as FAILED. dag_id=events_analytics_pipeline, task_id=dbt_run, execution_date=20251017T010000, start_date=20251017T023334, end_date=20251017T023334
[2025-10-17T02:33:34.358+0000] {standard_task_runner.py:107} ERROR - Failed to execute job 39 for task dbt_run (Bash command failed. The command returned a non-zero exit code 127.; 436)
[2025-10-17T02:33:34.399+0000] {local_task_job_runner.py:234} INFO - Task exited with return code 1
[2025-10-17T02:33:34.411+0000] {taskinstance.py:3280} INFO - 0 downstream tasks scheduled from follow-on schedule check
