[2025-10-17T02:18:03.763+0000] {taskinstance.py:1956} INFO - Dependencies all met for dep_context=non-requeueable deps ti=<TaskInstance: events_analytics_pipeline.dbt_run scheduled__2025-10-17T01:00:00+00:00 [queued]>
[2025-10-17T02:18:03.766+0000] {taskinstance.py:1956} INFO - Dependencies all met for dep_context=requeueable deps ti=<TaskInstance: events_analytics_pipeline.dbt_run scheduled__2025-10-17T01:00:00+00:00 [queued]>
[2025-10-17T02:18:03.766+0000] {taskinstance.py:2170} INFO - Starting attempt 2 of 3
[2025-10-17T02:18:03.771+0000] {taskinstance.py:2191} INFO - Executing <Task(BashOperator): dbt_run> on 2025-10-17 01:00:00+00:00
[2025-10-17T02:18:03.776+0000] {standard_task_runner.py:60} INFO - Started process 423 to run task
[2025-10-17T02:18:03.777+0000] {standard_task_runner.py:87} INFO - Running: ['airflow', 'tasks', 'run', 'events_analytics_pipeline', 'dbt_run', 'scheduled__2025-10-17T01:00:00+00:00', '--job-id', '38', '--raw', '--subdir', 'DAGS_FOLDER/events_pipeline_dag.py', '--cfg-path', '/tmp/tmpebs8g4bc']
[2025-10-17T02:18:03.780+0000] {standard_task_runner.py:88} INFO - Job 38: Subtask dbt_run
[2025-10-17T02:18:03.803+0000] {task_command.py:423} INFO - Running <TaskInstance: events_analytics_pipeline.dbt_run scheduled__2025-10-17T01:00:00+00:00 [running]> on host d7067dead38a
[2025-10-17T02:18:03.827+0000] {taskinstance.py:2480} INFO - Exporting env vars: AIRFLOW_CTX_DAG_OWNER='data-team' AIRFLOW_CTX_DAG_ID='events_analytics_pipeline' AIRFLOW_CTX_TASK_ID='dbt_run' AIRFLOW_CTX_EXECUTION_DATE='2025-10-17T01:00:00+00:00' AIRFLOW_CTX_TRY_NUMBER='2' AIRFLOW_CTX_DAG_RUN_ID='scheduled__2025-10-17T01:00:00+00:00'
[2025-10-17T02:18:03.827+0000] {subprocess.py:63} INFO - Tmp dir root location: /tmp
[2025-10-17T02:18:03.828+0000] {subprocess.py:75} INFO - Running command: ['/usr/bin/bash', '-c', 'dbt run --profiles-dir /opt/airflow/.dbt --project-dir /opt/airflow/event_gen']
[2025-10-17T02:18:03.834+0000] {subprocess.py:86} INFO - Output:
[2025-10-17T02:18:03.837+0000] {subprocess.py:93} INFO - /usr/bin/bash: line 1: dbt: command not found
[2025-10-17T02:18:03.838+0000] {subprocess.py:97} INFO - Command exited with return code 127
[2025-10-17T02:18:03.844+0000] {taskinstance.py:2698} ERROR - Task failed with exception
Traceback (most recent call last):
  File "/home/airflow/.local/lib/python3.11/site-packages/airflow/models/taskinstance.py", line 433, in _execute_task
    result = execute_callable(context=context, **execute_callable_kwargs)
             ^^^^^^^^^^^^^^^^^^^^^^^^^^^^^^^^^^^^^^^^^^^^^^^^^^^^^^^^^^^^
  File "/home/airflow/.local/lib/python3.11/site-packages/airflow/operators/bash.py", line 212, in execute
    raise AirflowException(
airflow.exceptions.AirflowException: Bash command failed. The command returned a non-zero exit code 127.
[2025-10-17T02:18:03.845+0000] {taskinstance.py:1138} INFO - Marking task as UP_FOR_RETRY. dag_id=events_analytics_pipeline, task_id=dbt_run, execution_date=20251017T010000, start_date=20251017T021803, end_date=20251017T021803
[2025-10-17T02:18:03.849+0000] {standard_task_runner.py:107} ERROR - Failed to execute job 38 for task dbt_run (Bash command failed. The command returned a non-zero exit code 127.; 423)
[2025-10-17T02:18:03.880+0000] {local_task_job_runner.py:234} INFO - Task exited with return code 1
[2025-10-17T02:18:03.888+0000] {taskinstance.py:3280} INFO - 0 downstream tasks scheduled from follow-on schedule check
