[2025-10-15T03:34:07.539+0000] {taskinstance.py:1956} INFO - Dependencies all met for dep_context=non-requeueable deps ti=<TaskInstance: events_analytics_pipeline.extract_and_load_to_clickhouse scheduled__2025-10-15T02:00:00+00:00 [queued]>
[2025-10-15T03:34:07.546+0000] {taskinstance.py:1956} INFO - Dependencies all met for dep_context=requeueable deps ti=<TaskInstance: events_analytics_pipeline.extract_and_load_to_clickhouse scheduled__2025-10-15T02:00:00+00:00 [queued]>
[2025-10-15T03:34:07.546+0000] {taskinstance.py:2170} INFO - Starting attempt 2 of 3
[2025-10-15T03:34:07.554+0000] {taskinstance.py:2191} INFO - Executing <Task(PythonOperator): extract_and_load_to_clickhouse> on 2025-10-15 02:00:00+00:00
[2025-10-15T03:34:07.559+0000] {standard_task_runner.py:60} INFO - Started process 1278 to run task
[2025-10-15T03:34:07.563+0000] {standard_task_runner.py:87} INFO - Running: ['***', 'tasks', 'run', 'events_analytics_pipeline', 'extract_and_load_to_clickhouse', 'scheduled__2025-10-15T02:00:00+00:00', '--job-id', '22', '--raw', '--subdir', 'DAGS_FOLDER/events_pipeline_dag.py', '--cfg-path', '/tmp/tmpo8ec66hi']
[2025-10-15T03:34:07.566+0000] {standard_task_runner.py:88} INFO - Job 22: Subtask extract_and_load_to_clickhouse
[2025-10-15T03:34:07.593+0000] {task_command.py:423} INFO - Running <TaskInstance: events_analytics_pipeline.extract_and_load_to_clickhouse scheduled__2025-10-15T02:00:00+00:00 [running]> on host 96cb876c5fc2
[2025-10-15T03:34:07.621+0000] {taskinstance.py:2480} INFO - Exporting env vars: AIRFLOW_CTX_DAG_OWNER='data-team' AIRFLOW_CTX_DAG_ID='events_analytics_pipeline' AIRFLOW_CTX_TASK_ID='extract_and_load_to_clickhouse' AIRFLOW_CTX_EXECUTION_DATE='2025-10-15T02:00:00+00:00' AIRFLOW_CTX_TRY_NUMBER='2' AIRFLOW_CTX_DAG_RUN_ID='scheduled__2025-10-15T02:00:00+00:00'
[2025-10-15T03:34:07.621+0000] {events_pipeline_dag.py:67} INFO - Connecting to PostgreSQL...
[2025-10-15T03:34:07.622+0000] {events_pipeline_dag.py:70} INFO - Extracting data from PostgreSQL...
[2025-10-15T03:34:07.627+0000] {taskinstance.py:2698} ERROR - Task failed with exception
Traceback (most recent call last):
  File "/home/airflow/.local/lib/python3.11/site-packages/sqlalchemy/engine/base.py", line 1910, in _execute_context
    self.dialect.do_execute(
  File "/home/airflow/.local/lib/python3.11/site-packages/sqlalchemy/engine/default.py", line 736, in do_execute
    cursor.execute(statement, parameters)
psycopg2.errors.UndefinedTable: relation "events" does not exist
LINE 1: SELECT * FROM events
                      ^


The above exception was the direct cause of the following exception:

Traceback (most recent call last):
  File "/home/airflow/.local/lib/python3.11/site-packages/airflow/models/taskinstance.py", line 433, in _execute_task
    result = execute_callable(context=context, **execute_callable_kwargs)
             ^^^^^^^^^^^^^^^^^^^^^^^^^^^^^^^^^^^^^^^^^^^^^^^^^^^^^^^^^^^^
  File "/home/airflow/.local/lib/python3.11/site-packages/airflow/operators/python.py", line 199, in execute
    return_value = self.execute_callable()
                   ^^^^^^^^^^^^^^^^^^^^^^^
  File "/home/airflow/.local/lib/python3.11/site-packages/airflow/operators/python.py", line 216, in execute_callable
    return self.python_callable(*self.op_args, **self.op_kwargs)
           ^^^^^^^^^^^^^^^^^^^^^^^^^^^^^^^^^^^^^^^^^^^^^^^^^^^^^
  File "/opt/airflow/dags/events_pipeline_dag.py", line 72, in extract_and_load_to_clickhouse
    events_df = pd.read_sql(query, pg_engine)
                ^^^^^^^^^^^^^^^^^^^^^^^^^^^^^
  File "/home/airflow/.local/lib/python3.11/site-packages/pandas/io/sql.py", line 682, in read_sql
    return pandas_sql.read_query(
           ^^^^^^^^^^^^^^^^^^^^^^
  File "/home/airflow/.local/lib/python3.11/site-packages/pandas/io/sql.py", line 1776, in read_query
    result = self.execute(sql, params)
             ^^^^^^^^^^^^^^^^^^^^^^^^^
  File "/home/airflow/.local/lib/python3.11/site-packages/pandas/io/sql.py", line 1599, in execute
    return self.con.exec_driver_sql(sql, *args)
           ^^^^^^^^^^^^^^^^^^^^^^^^^^^^^^^^^^^^
  File "/home/airflow/.local/lib/python3.11/site-packages/sqlalchemy/engine/base.py", line 1770, in exec_driver_sql
    return self._exec_driver_sql(
           ^^^^^^^^^^^^^^^^^^^^^^
  File "/home/airflow/.local/lib/python3.11/site-packages/sqlalchemy/engine/base.py", line 1674, in _exec_driver_sql
    ret = self._execute_context(
          ^^^^^^^^^^^^^^^^^^^^^^
  File "/home/airflow/.local/lib/python3.11/site-packages/sqlalchemy/engine/base.py", line 1953, in _execute_context
    self._handle_dbapi_exception(
  File "/home/airflow/.local/lib/python3.11/site-packages/sqlalchemy/engine/base.py", line 2134, in _handle_dbapi_exception
    util.raise_(
  File "/home/airflow/.local/lib/python3.11/site-packages/sqlalchemy/util/compat.py", line 211, in raise_
    raise exception
  File "/home/airflow/.local/lib/python3.11/site-packages/sqlalchemy/engine/base.py", line 1910, in _execute_context
    self.dialect.do_execute(
  File "/home/airflow/.local/lib/python3.11/site-packages/sqlalchemy/engine/default.py", line 736, in do_execute
    cursor.execute(statement, parameters)
sqlalchemy.exc.ProgrammingError: (psycopg2.errors.UndefinedTable) relation "events" does not exist
LINE 1: SELECT * FROM events
                      ^

[SQL: SELECT * FROM events]
(Background on this error at: https://sqlalche.me/e/14/f405)
[2025-10-15T03:34:07.631+0000] {taskinstance.py:1138} INFO - Marking task as UP_FOR_RETRY. dag_id=events_analytics_pipeline, task_id=extract_and_load_to_clickhouse, execution_date=20251015T020000, start_date=20251015T033407, end_date=20251015T033407
[2025-10-15T03:34:07.634+0000] {standard_task_runner.py:107} ERROR - Failed to execute job 22 for task extract_and_load_to_clickhouse ((psycopg2.errors.UndefinedTable) relation "events" does not exist
LINE 1: SELECT * FROM events
                      ^

[SQL: SELECT * FROM events]
(Background on this error at: https://sqlalche.me/e/14/f405); 1278)
[2025-10-15T03:34:07.663+0000] {local_task_job_runner.py:234} INFO - Task exited with return code 1
[2025-10-15T03:34:07.672+0000] {taskinstance.py:3280} INFO - 0 downstream tasks scheduled from follow-on schedule check
