[2025-10-13T14:59:10.047+0000] {taskinstance.py:1956} INFO - Dependencies all met for dep_context=non-requeueable deps ti=<TaskInstance: events_analytics_pipeline.dbt_run manual__2025-10-13T14:48:58.664092+00:00 [queued]>
[2025-10-13T14:59:10.050+0000] {taskinstance.py:1956} INFO - Dependencies all met for dep_context=requeueable deps ti=<TaskInstance: events_analytics_pipeline.dbt_run manual__2025-10-13T14:48:58.664092+00:00 [queued]>
[2025-10-13T14:59:10.050+0000] {taskinstance.py:2170} INFO - Starting attempt 3 of 3
[2025-10-13T14:59:10.054+0000] {taskinstance.py:2191} INFO - Executing <Task(BashOperator): dbt_run> on 2025-10-13 14:48:58.664092+00:00
[2025-10-13T14:59:10.057+0000] {standard_task_runner.py:60} INFO - Started process 459 to run task
[2025-10-13T14:59:10.058+0000] {standard_task_runner.py:87} INFO - Running: ['***', 'tasks', 'run', 'events_analytics_pipeline', 'dbt_run', 'manual__2025-10-13T14:48:58.664092+00:00', '--job-id', '52', '--raw', '--subdir', 'DAGS_FOLDER/events_pipeline_dag.py', '--cfg-path', '/tmp/tmp1u0qv4rd']
[2025-10-13T14:59:10.060+0000] {standard_task_runner.py:88} INFO - Job 52: Subtask dbt_run
[2025-10-13T14:59:10.093+0000] {task_command.py:423} INFO - Running <TaskInstance: events_analytics_pipeline.dbt_run manual__2025-10-13T14:48:58.664092+00:00 [running]> on host 7fd364930f15
[2025-10-13T14:59:10.124+0000] {taskinstance.py:2480} INFO - Exporting env vars: AIRFLOW_CTX_DAG_OWNER='data-team' AIRFLOW_CTX_DAG_ID='events_analytics_pipeline' AIRFLOW_CTX_TASK_ID='dbt_run' AIRFLOW_CTX_EXECUTION_DATE='2025-10-13T14:48:58.664092+00:00' AIRFLOW_CTX_TRY_NUMBER='3' AIRFLOW_CTX_DAG_RUN_ID='manual__2025-10-13T14:48:58.664092+00:00'
[2025-10-13T14:59:10.125+0000] {subprocess.py:63} INFO - Tmp dir root location: /tmp
[2025-10-13T14:59:10.125+0000] {subprocess.py:75} INFO - Running command: ['/usr/bin/bash', '-c', 'cd /opt/***/event_gen && dbt run --profiles-dir /opt/***/.dbt']
[2025-10-13T14:59:10.129+0000] {subprocess.py:86} INFO - Output:
[2025-10-13T14:59:10.783+0000] {subprocess.py:93} INFO - [0m14:59:10  Running with dbt=1.10.13
[2025-10-13T14:59:10.785+0000] {subprocess.py:93} INFO - [0m14:59:10  Encountered an error:
[2025-10-13T14:59:10.785+0000] {subprocess.py:93} INFO - Runtime Error
[2025-10-13T14:59:10.785+0000] {subprocess.py:93} INFO -   Could not find profile named 'event_gen'
[2025-10-13T14:59:12.379+0000] {subprocess.py:97} INFO - Command exited with return code 2
[2025-10-13T14:59:12.386+0000] {taskinstance.py:2698} ERROR - Task failed with exception
Traceback (most recent call last):
  File "/home/airflow/.local/lib/python3.11/site-packages/airflow/models/taskinstance.py", line 433, in _execute_task
    result = execute_callable(context=context, **execute_callable_kwargs)
             ^^^^^^^^^^^^^^^^^^^^^^^^^^^^^^^^^^^^^^^^^^^^^^^^^^^^^^^^^^^^
  File "/home/airflow/.local/lib/python3.11/site-packages/airflow/operators/bash.py", line 212, in execute
    raise AirflowException(
airflow.exceptions.AirflowException: Bash command failed. The command returned a non-zero exit code 2.
[2025-10-13T14:59:12.388+0000] {taskinstance.py:1138} INFO - Marking task as FAILED. dag_id=events_analytics_pipeline, task_id=dbt_run, execution_date=20251013T144858, start_date=20251013T145910, end_date=20251013T145912
[2025-10-13T14:59:12.392+0000] {standard_task_runner.py:107} ERROR - Failed to execute job 52 for task dbt_run (Bash command failed. The command returned a non-zero exit code 2.; 459)
[2025-10-13T14:59:12.417+0000] {local_task_job_runner.py:234} INFO - Task exited with return code 1
[2025-10-13T14:59:12.426+0000] {taskinstance.py:3280} INFO - 0 downstream tasks scheduled from follow-on schedule check
